# Bug Fix: HTTPException 'not callable' Error

## Problem

After implementing X-API-Key authentication, the API endpoints were failing with:

```
TypeError: 'HTTPException' object is not callable
INFO: 127.0.0.1:64727 - "GET /api/clinics/?skip=0&limit=50 HTTP/1.1" 500 Internal Server Error
```

## Root Causes

### 1. HTTPBearer Auto-Error Change
When I changed `HTTPBearer()` to `HTTPBearer(auto_error=False)`, the `credentials` parameter became optional (could be `None`). However, the `get_current_user` function still assumed `credentials` would always have a value.

**Location**: `app/auth/dependencies.py:16`
```python
# BEFORE (broken)
async def get_current_user(credentials: HTTPAuthorizationCredentials = Depends(security)) -> dict:
    token = credentials.credentials  # ERROR: credentials could be None

# AFTER (fixed)
async def get_current_user(credentials: Optional[HTTPAuthorizationCredentials] = Depends(security)) -> dict:
    if not credentials:
        raise HTTPException(
            status_code=status.HTTP_401_UNAUTHORIZED,
            detail="Bearer token required"
        )
    token = credentials.credentials
```

### 2. Global Exception Handler Issue
The global exception handler was returning `HTTPException` instead of returning a proper response.

**Location**: `main.py:550`
```python
# BEFORE (broken)
@app.exception_handler(Exception)
async def global_exception_handler(request, exc):
    print(f"Global exception: {exc}")
    return HTTPException(  # ERROR: Should not return HTTPException
        status_code=500,
        detail="Internal server error"
    )

# AFTER (fixed)
@app.exception_handler(Exception)
async def global_exception_handler(request, exc):
    import traceback
    print(f"Global exception: {exc}")
    print(f"Traceback: {traceback.format_exc()}")
    
    from fastapi.responses import JSONResponse
    return JSONResponse(
        status_code=500,
        content={"detail": "Internal server error", "error": str(exc)}
    )
```

## Solution Applied

1. **Fixed `get_current_user` function**: Added proper None checking for credentials parameter
2. **Fixed global exception handler**: Return proper JSONResponse instead of HTTPException
3. **Added better error handling**: Include traceback for debugging

## Testing Results

### Before Fix:
```bash
curl "http://localhost:8000/api/clinics/?skip=0&limit=5"
# Result: Internal Server Error (500)
```

### After Fix:
```bash
curl "http://localhost:8000/api/clinics/?skip=0&limit=5"
# Result: {"detail":"Bearer token required"} (401) ✅

curl -H "X-API-Key: test123456" "http://localhost:8000/api/test-key"
# Result: {"message":"X-API-Key authentication successful!"} ✅
```

## Key Learnings

1. **HTTPException Usage**: Always use `raise HTTPException(...)` never `return HTTPException(...)`
2. **Auto-Error False**: When using `auto_error=False` in FastAPI security dependencies, always check for None values
3. **Exception Handlers**: Return proper Response objects (JSONResponse, etc.) not HTTPException objects
4. **Testing**: Always test both success and error paths after making authentication changes

## Status: ✅ RESOLVED

All API endpoints now work correctly with proper error handling and X-API-Key authentication in Swagger UI.